<mujoco model="ergoCub">
  <compiler angle="radian" meshdir="../../../ergoCub/meshes/simmechanics/" autolimits="true" />
 <default> 
  <default class="pos_control">
      <joint damping="1" frictionloss="1"/>
      <general biastype="affine" gainprm="1000" biasprm="0 -1000 -100" forcerange="-30 30"/>
  </default>
</default>

  <asset>
    <mesh name="sim_ecub_root_link_prt" file="sim_ecub_root_link_prt.stl" scale="0.001 0.001 0.001" />
    <mesh name="sim_ecub_r_hip_1_prt" file="sim_ecub_r_hip_1_prt.stl" scale="0.001 0.001 0.001" />
    <mesh name="sim_ecub_r_hip_2_prt" file="sim_ecub_r_hip_2_prt.stl" scale="0.001 0.001 0.001" />
    <mesh name="sim_ecub_r_hip_3_prt" file="sim_ecub_r_hip_3_prt.stl" scale="0.001 0.001 0.001" />
    <mesh name="sim_ecub_r_upper_leg_prt" file="sim_ecub_r_upper_leg_prt.stl" scale="0.001 0.001 0.001" />
    <mesh name="sim_ecub_r_lower_leg_prt" file="sim_ecub_r_lower_leg_prt.stl" scale="0.001 0.001 0.001" />
    <mesh name="sim_ecub_r_ankle_1_prt" file="sim_ecub_r_ankle_1_prt.stl" scale="0.001 0.001 0.001" />
    <mesh name="sim_ecub_r_ankle_2_prt" file="sim_ecub_r_ankle_2_prt.stl" scale="0.001 0.001 0.001" />
    <mesh name="sim_ecub_r_foot_rear_prt" file="sim_ecub_r_foot_rear_prt.stl" scale="0.001 0.001 0.001" />
    <mesh name="sim_ecub_r_foot_front_prt" file="sim_ecub_r_foot_front_prt.stl" scale="0.001 0.001 0.001" />
    <mesh name="sim_ecub_l_hip_1_prt" file="sim_ecub_l_hip_1_prt.stl" scale="0.001 0.001 0.001" />
    <mesh name="sim_ecub_l_hip_2_prt" file="sim_ecub_l_hip_2_prt.stl" scale="0.001 0.001 0.001" />
    <mesh name="sim_ecub_l_hip_3_prt" file="sim_ecub_l_hip_3_prt.stl" scale="0.001 0.001 0.001" />
    <mesh name="sim_ecub_l_upper_leg_prt" file="sim_ecub_l_upper_leg_prt.stl" scale="0.001 0.001 0.001" />
    <mesh name="sim_ecub_l_lower_leg_prt" file="sim_ecub_l_lower_leg_prt.stl" scale="0.001 0.001 0.001" />
    <mesh name="sim_ecub_l_ankle_1_prt" file="sim_ecub_l_ankle_1_prt.stl" scale="0.001 0.001 0.001" />
    <mesh name="sim_ecub_l_ankle_2_prt" file="sim_ecub_l_ankle_2_prt.stl" scale="0.001 0.001 0.001" />
    <mesh name="sim_ecub_l_foot_front_prt" file="sim_ecub_l_foot_front_prt.stl" scale="0.001 0.001 0.001" />
    <mesh name="sim_ecub_l_foot_rear_prt" file="sim_ecub_l_foot_rear_prt.stl" scale="0.001 0.001 0.001" />
    <mesh name="sim_ecub_torso_1_prt" file="sim_ecub_torso_1_prt.stl" scale="0.001 0.001 0.001" />
    <mesh name="sim_ecub_torso_2_prt" file="sim_ecub_torso_2_prt.stl" scale="0.001 0.001 0.001" />
    <mesh name="sim_ecub_chest_prt" file="sim_ecub_chest_prt.stl" scale="0.001 0.001 0.001" />
    <mesh name="sim_ecub_head_neck_2_prt" file="sim_ecub_head_neck_2_prt.stl" scale="0.001 0.001 0.001" />
    <mesh name="sim_ecub_head_neck_3_prt" file="sim_ecub_head_neck_3_prt.stl" scale="0.001 0.001 0.001" />
    <mesh name="sim_ecub_head_prt" file="sim_ecub_head_prt.stl" scale="0.001 0.001 0.001" />
    <mesh name="sim_ecub_realsense_prt" file="sim_ecub_realsense_prt.stl" scale="0.001 0.001 0.001" />
    <mesh name="sim_ecub_r_shoulder_1_prt" file="sim_ecub_r_shoulder_1_prt.stl" scale="0.001 0.001 0.001" />
    <mesh name="sim_ecub_r_shoulder_2_prt" file="sim_ecub_r_shoulder_2_prt.stl" scale="0.001 0.001 0.001" />
    <mesh name="sim_ecub_r_shoulder_3_prt" file="sim_ecub_r_shoulder_3_prt.stl" scale="0.001 0.001 0.001" />
    <mesh name="sim_ecub_r_upperarm_prt" file="sim_ecub_r_upperarm_prt.stl" scale="0.001 0.001 0.001" />
    <mesh name="sim_ecub_r_forearm_prt" file="sim_ecub_r_forearm_prt.stl" scale="0.001 0.001 0.001" />
    <mesh name="sim_ecub_r_wrist_1_prt" file="sim_ecub_r_wrist_1_prt.stl" scale="0.001 0.001 0.001" />
    <mesh name="sim_ecub_r_wrist_2_prt" file="sim_ecub_r_wrist_2_prt.stl" scale="0.001 0.001 0.001" />
    <mesh name="sim_ecub_r_hand_palm_prt" file="sim_ecub_r_hand_palm_prt.stl" scale="0.001 0.001 0.001" />
    <mesh name="sim_ecub_r_hand_pinkie_1_prt" file="sim_ecub_r_hand_pinkie_1_prt.stl" scale="0.001 0.001 0.001" />
    <mesh name="sim_ecub_r_hand_pinkie_2_prt" file="sim_ecub_r_hand_pinkie_2_prt.stl" scale="0.001 0.001 0.001" />
    <mesh name="sim_ecub_r_hand_thumb_1_prt" file="sim_ecub_r_hand_thumb_1_prt.stl" scale="0.001 0.001 0.001" />
    <mesh name="sim_ecub_r_hand_thumb_2_prt" file="sim_ecub_r_hand_thumb_2_prt.stl" scale="0.001 0.001 0.001" />
    <mesh name="sim_ecub_r_hand_thumb_3_prt" file="sim_ecub_r_hand_thumb_3_prt.stl" scale="0.001 0.001 0.001" />
    <mesh name="sim_ecub_r_hand_middle_1_prt" file="sim_ecub_r_hand_middle_1_prt.stl" scale="0.001 0.001 0.001" />
    <mesh name="sim_ecub_r_hand_middle_2_prt" file="sim_ecub_r_hand_middle_2_prt.stl" scale="0.001 0.001 0.001" />
    <mesh name="sim_ecub_r_hand_ring_1_prt" file="sim_ecub_r_hand_ring_1_prt.stl" scale="0.001 0.001 0.001" />
    <mesh name="sim_ecub_r_hand_ring_2_prt" file="sim_ecub_r_hand_ring_2_prt.stl" scale="0.001 0.001 0.001" />
    <mesh name="sim_ecub_r_hand_index_1_prt" file="sim_ecub_r_hand_index_1_prt.stl" scale="0.001 0.001 0.001" />
    <mesh name="sim_ecub_r_hand_index_2_prt" file="sim_ecub_r_hand_index_2_prt.stl" scale="0.001 0.001 0.001" />
    <mesh name="sim_ecub_r_hand_index_3_prt" file="sim_ecub_r_hand_index_3_prt.stl" scale="0.001 0.001 0.001" />
    <mesh name="sim_ecub_l_shoulder_1_prt" file="sim_ecub_l_shoulder_1_prt.stl" scale="0.001 0.001 0.001" />
    <mesh name="sim_ecub_l_shoulder_2_prt" file="sim_ecub_l_shoulder_2_prt.stl" scale="0.001 0.001 0.001" />
    <mesh name="sim_ecub_l_shoulder_3_prt" file="sim_ecub_l_shoulder_3_prt.stl" scale="0.001 0.001 0.001" />
    <mesh name="sim_ecub_l_upperarm_prt" file="sim_ecub_l_upperarm_prt.stl" scale="0.001 0.001 0.001" />
    <mesh name="sim_ecub_l_forearm_prt" file="sim_ecub_l_forearm_prt.stl" scale="0.001 0.001 0.001" />
    <mesh name="sim_ecub_l_wrist_1_prt" file="sim_ecub_l_wrist_1_prt.stl" scale="0.001 0.001 0.001" />
    <mesh name="sim_ecub_l_wrist_2_prt" file="sim_ecub_l_wrist_2_prt.stl" scale="0.001 0.001 0.001" />
    <mesh name="sim_ecub_l_hand_palm_prt" file="sim_ecub_l_hand_palm_prt.stl" scale="0.001 0.001 0.001" />
    <mesh name="sim_ecub_l_hand_ring_1_prt" file="sim_ecub_l_hand_ring_1_prt.stl" scale="0.001 0.001 0.001" />
    <mesh name="sim_ecub_l_hand_ring_2_prt" file="sim_ecub_l_hand_ring_2_prt.stl" scale="0.001 0.001 0.001" />
    <mesh name="sim_ecub_l_hand_index_1_prt" file="sim_ecub_l_hand_index_1_prt.stl" scale="0.001 0.001 0.001" />
    <mesh name="sim_ecub_l_hand_index_2_prt" file="sim_ecub_l_hand_index_2_prt.stl" scale="0.001 0.001 0.001" />
    <mesh name="sim_ecub_l_hand_index_3_prt" file="sim_ecub_l_hand_index_3_prt.stl" scale="0.001 0.001 0.001" />
    <mesh name="sim_ecub_l_hand_middle_1_prt" file="sim_ecub_l_hand_middle_1_prt.stl" scale="0.001 0.001 0.001" />
    <mesh name="sim_ecub_l_hand_middle_2_prt" file="sim_ecub_l_hand_middle_2_prt.stl" scale="0.001 0.001 0.001" />
    <mesh name="sim_ecub_l_hand_thumb_1_prt" file="sim_ecub_l_hand_thumb_1_prt.stl" scale="0.001 0.001 0.001" />
    <mesh name="sim_ecub_l_hand_thumb_2_prt" file="sim_ecub_l_hand_thumb_2_prt.stl" scale="0.001 0.001 0.001" />
    <mesh name="sim_ecub_l_hand_thumb_3_prt" file="sim_ecub_l_hand_thumb_3_prt.stl" scale="0.001 0.001 0.001" />
    <mesh name="sim_ecub_l_hand_pinkie_1_prt" file="sim_ecub_l_hand_pinkie_1_prt.stl" scale="0.001 0.001 0.001" />
    <mesh name="sim_ecub_l_hand_pinkie_2_prt" file="sim_ecub_l_hand_pinkie_2_prt.stl" scale="0.001 0.001 0.001" />
  </asset>
  <worldbody>
    <body name="root_link" gravcomp="0">
      <inertial pos="0.00182766 -7.75984e-05 0.0173173" quat="0.706137 0.0372939 0.0370242 0.706123" mass="3.82375" diaginertia="1.01479 1.01041 1.01" />
      <joint name="floating_joint" type="free" />
      <geom pos="0 0 0.1785" quat="0.707107 0 0 0.707107" type="mesh" contype="0" conaffinity="0" rgba="0.7 0.7 0.7 1" mesh="sim_ecub_root_link_prt" />
      <body name="r_hip_1" pos="0.0211 -0.0505 0" gravcomp="0" >
        <inertial pos="-0.0040321 -0.0282494 -0.000674" quat="0.707107 0 0 0.707107" mass="2.23209" diaginertia="0.01 0.01 0.01" />
        <joint name="r_hip_pitch" pos="0 0 0" axis="0 -1 0" range="-0.785398 2.00713" damping="2" />
        <geom pos="-0.0211 0.0505 0.1785" quat="0.707107 0 0 0.707107" type="mesh" contype="0" conaffinity="0" rgba="0.7 0.7 0.7 1" mesh="sim_ecub_r_hip_1_prt" />
        <body name="r_hip_2" pos="-0.04725 -0.0331 -0.009" gravcomp="0">
          <inertial pos="0.0206737 0.00690112 -0.0935168" quat="0.976838 0.0551628 -0.206419 0.0116567" mass="3.9815" diaginertia="0.0329439 0.0329439 0.02" />
          <joint name="r_hip_roll" pos="0 0 0" axis="-1 0 0" range="-0.610865 1.95477" damping="2" />
          <geom pos="0.0262 0.0836 0.1875" quat="0.707107 0 0 0.707107" type="mesh" contype="0" conaffinity="0" rgba="0.7 0.7 0.7 1" mesh="sim_ecub_r_hip_2_prt" />
          <geom pos="0.0262 0.0836 0.1875" quat="0.707107 0 0 0.707107" type="mesh" contype="0" conaffinity="0" rgba="0.3 0.3 0.3 1" mesh="sim_ecub_r_hip_3_prt" />
          <body name="r_upper_leg" pos="0.0367 0.015 -0.1624" quat="1 0 0 5.9369e-07" gravcomp="0">
            <inertial pos="0.00851748 -0.0144685 -0.12675" quat="0.707107 0 0 0.707107" mass="2.78492" diaginertia="0.0121093 0.0118603 0.01" />
            <joint name="r_hip_yaw" pos="0 0 0" axis="0 0 -1" range="-1.39626 1.39626" damping="2" />
            <geom pos="-0.0105 0.0686 0.3499" quat="0.707107 0 0 0.707107" type="mesh" contype="0" conaffinity="0" rgba="0.7 0.7 0.7 1" mesh="sim_ecub_r_upper_leg_prt" />
            <body name="r_lower_leg" pos="0.0106 0.00789999 -0.1797" quat="0 1 -5.9369e-07 0" gravcomp="0">
              <inertial pos="0.0011585 0.0062002 0.214259" quat="0 0.707107 -0.707107 0" mass="3.74161" diaginertia="0.0472543 0.0460139 0.0147852" />
              <joint name="r_knee" pos="0 0 0" axis="0 1 0" range="-1.42173 0.172665" damping="2" />
              <geom pos="-0.0211 -0.0607 -0.5296" quat="0 0.707107 -0.707107 0" type="mesh" contype="0" conaffinity="0" rgba="0.3 0.3 0.3 1" mesh="sim_ecub_r_lower_leg_prt" />
              <body name="r_ankle_1" pos="0 0.0319 0.321" quat="0 1 0 0" gravcomp="0">
                <inertial pos="-0.0013672 -0.0006602 -0.014087" quat="0.5 0.5 0.5 0.5" mass="0.348128" diaginertia="0.0105754 0.0104627 0.01" />
                <joint name="r_ankle_pitch" pos="0 0 0" axis="0 1 0" range="-0.785398 0.785398" damping="2" />
                <geom pos="-0.0211 0.0926 0.8506" quat="0.707107 0 0 0.707107" type="mesh" contype="0" conaffinity="0" rgba="0.7 0.7 0.7 1" mesh="sim_ecub_r_ankle_1_prt" />
                <body name="r_ankle_2" pos="-0.05275 0.0182 -0.035" gravcomp="1">
                  <inertial pos="0.0575787 -4.46421e-05 -0.0459216" quat="0.948048 0.000976363 -0.318127 0.000296289" mass="2.98403" diaginertia="1.03499 1.03431 1.03249" />
                  <joint name="r_ankle_roll" pos="0 0 0" axis="-1 0 0" range="-0.436332 0.436332" damping="3" />
                  <geom name = "r_ankle" pos="0.03165 0.0744 0.8856" quat="0.707107 0 0 0.707107" type="mesh"  contype="0" conaffinity="0"  rgba="0.3 0.3 0.3 1" mesh="sim_ecub_r_ankle_2_prt" />
                  <geom name = "rigth_foot_rear" pos="0.0316 0.0744 0.8856" quat="0.707107 0 0 0.707107" type="mesh" rgba="1 0.51 0 1" mesh="sim_ecub_r_foot_rear_prt" />
                  <geom name = "rigth_foot_front" pos="0.03165 0.0744 0.8856" quat="0.707107 0 0 0.707107" type="mesh" rgba="1 0.51 0 1" mesh="sim_ecub_r_foot_front_prt" />
                </body>
              </body>
            </body>
          </body>
        </body>
      </body>
      <body name="l_hip_1" pos="0.0211 0.0505 0" gravcomp="0">
        <inertial pos="-0.0040154 0.0282473 -0.000681" quat="0.5 0.5 0.5 0.5" mass="2.23177" diaginertia="0.0126953 0.012461 0.0122109" />
        <joint name="l_hip_pitch" pos="0 0 0" axis="0 -1 0" range="-0.785398 2.00713" damping="2" />
        <geom pos="-0.0211 -0.0505 0.1785" quat="0.707107 0 0 0.707107" type="mesh" contype="0" conaffinity="0" rgba="0.7 0.7 0.7 1" mesh="sim_ecub_l_hip_1_prt" />
        <body name="l_hip_2" pos="-0.04725 0.0331 -0.009" gravcomp="0">
          <inertial pos="0.0206874 -0.00690172 -0.0935735" quat="0.978716 -0.0789815 -0.189155 -0.00986691" mass="3.98136" diaginertia="0.0431527 0.0384988 0.0292505" />
          <joint name="l_hip_roll" pos="0 0 0" axis="1 0 0" range="-0.610865 1.95477" damping="2" />
          <geom pos="0.02615 -0.0836 0.1875" quat="0.707107 0 0 0.707107" type="mesh" contype="0" conaffinity="0" rgba="0.7 0.7 0.7 1" mesh="sim_ecub_l_hip_2_prt" />
          <geom pos="0.02615 -0.0836 0.1875" quat="0.707107 0 0 0.707107" type="mesh" contype="0" conaffinity="0" rgba="0.3 0.3 0.3 1" mesh="sim_ecub_l_hip_3_prt" />
          <body name="l_upper_leg" pos="0.0367 -0.015 -0.1624" gravcomp="0">
            <inertial pos="0.0085035 0.0144849 -0.126747" quat="0 0.707107 0 0.707107" mass="2.78492" diaginertia="0.0122536 0.0121099 0.0118524" />
            <joint name="l_hip_yaw" pos="0 0 0" axis="0 0 1" range="-1.39626 1.39626" damping="2" />
            <geom pos="-0.01055 -0.0686 0.3499" quat="0.707107 0 0 0.707107" type="mesh"contype="0" conaffinity="0"  rgba="0.7 0.7 0.7 1" mesh="sim_ecub_l_upper_leg_prt" />
            <body name="l_lower_leg" pos="0.0106 -0.0079 -0.1797" quat="0 1 0 0" gravcomp="0">
              <inertial pos="0.0013845 -0.0061871 0.21426" quat="0 0.707107 -0.707107 0" mass="3.74161" diaginertia="0.0472543 0.0460139 0.0147852" />
              <joint name="l_knee" pos="0 0 0" axis="0 1 0" range="-1.42173 0.172665" damping="2" />
              <geom pos="-0.02115 0.0607 -0.5296" quat="0 0.707107 -0.707107 0" type="mesh" contype="0" conaffinity="0" rgba="0.3 0.3 0.3 1" mesh="sim_ecub_l_lower_leg_prt" />
              <body name="l_ankle_1" pos="0 -0.0319 0.321" quat="0 1 0 0" gravcomp="0">
                <inertial pos="-0.0013852 0.0006602 -0.014087" quat="0.5 0.5 0.5 0.5" mass="0.348128" diaginertia="0.0105753 0.0104627 0.0102474" />
                <joint name="l_ankle_pitch" pos="0 0 0" axis="0 1 0" range="-0.785398 0.785398" damping="2" />
                <geom pos="-0.02115 -0.0926 0.8506" quat="0.707107 0 0 0.707107" type="mesh" contype="0" conaffinity="0" rgba="0.7 0.7 0.7 1" mesh="sim_ecub_l_ankle_1_prt" />
                <body name="l_ankle_2" pos="-0.05275 -0.0182 -0.035" gravcomp="1">
                  <inertial pos="0.0575766 -5.0584e-05 -0.0459216" quat="0.330076 0.625339 0.624632 0.331415" mass="2.98403" diaginertia="1.03405 1.03332 1.03074" />
                  <joint name="l_ankle_roll" pos="0 0 0" axis="1 0 0" range="-0.436332 0.436332" damping="3" />
                  <geom name = "left_ankle" pos="0.0316 -0.0744 0.8856" quat="0.707107 0 0 0.707107"   contype="0" conaffinity="0"  type="mesh" rgba="0.3 0.3 0.3 1" mesh="sim_ecub_l_ankle_2_prt" />
                  <geom name = "left_foot_front" pos="0.0316 -0.0744 0.8856" quat="0.707107 0 0 0.707107" type="mesh" rgba="1 0.51 0 1" mesh="sim_ecub_l_foot_front_prt" />
                  <geom name = "left_foot_rear" pos="0.0316 -0.0744 0.8856" quat="0.707107 0 0 0.707107" type="mesh" rgba="1 0.51 0 1" mesh="sim_ecub_l_foot_rear_prt" />
                </body>
              </body>
            </body>
          </body>
        </body>
      </body>
      <body name="torso_1" pos="0 0 0.0605" gravcomp="1">
        <inertial pos="-0.00963997 0.00061685 0.0824423" quat="0.707107 0 0 0.707107" mass="2.01685" diaginertia="0.01 0.01 0.01" />
        <joint name="torso_roll" pos="0 0 0" axis="1 0 0" range="-0.401426 0.401426" damping="3" />
        <geom pos="0 0 0.118" quat="0.707107 0 0 0.707107" type="mesh" contype="0" conaffinity="0" rgba="0.7 0.7 0.7 1" mesh="sim_ecub_torso_1_prt" />
        <body name="torso_2" pos="0 0 0.118" gravcomp="1">
          <inertial pos="0.00157247 0.00362235 0.0260195" quat="0.707107 0 0 0.707107" mass="0.705163" diaginertia="0.01 0.01 0.01" />
          <joint name="torso_pitch" pos="0 0 0" axis="0 1 0" range="-0.314159 0.785398" damping="3" />
          <geom quat="0.707107 0 0 0.707107" type="mesh" contype="0" conaffinity="0" rgba="0.7 0.7 0.7 1" mesh="sim_ecub_torso_2_prt" />
          <body name="chest" pos="0 0 0.06447" gravcomp="1">
            <inertial pos="0.00261294 -1.03509e-05 0.206588" quat="0.719877 0.0364314 0.0392444 0.692033" mass="14.7812" diaginertia="4.4141 4.40704 4.0804" />
            <joint name="torso_yaw" pos="0 0 0" axis="0 0 1" range="-0.750492 0.750492" damping="3" />
            <geom pos="0 0 -0.06447" quat="0.707107 0 0 0.707107" type="mesh" rgba="0.3 0.3 0.3 1" mesh="sim_ecub_chest_prt" />
            <geom pos="0 -5e-05 -0.06447" quat="0.707107 0 0 0.707107" type="mesh" contype="0" conaffinity="0" rgba="0.7 0.7 0.7 1" mesh="sim_ecub_head_neck_2_prt" />
            <geom pos="0 0 -0.06447" quat="0.707107 0 0 0.707107" type="mesh" contype="0" conaffinity="0" rgba="0.7 0.7 0.7 1" mesh="sim_ecub_head_neck_3_prt" />
            <geom pos="0 0 -0.06447" quat="0.707107 0 0 0.707107" type="mesh" contype="0" conaffinity="0" rgba="0.7 0.7 0.7 1" mesh="sim_ecub_head_prt" />
            <geom pos="0 0 -0.06447" quat="0.707107 0 0 0.707107" type="mesh" contype="0" conaffinity="0" rgba="0 1 0 1" mesh="sim_ecub_realsense_prt" />
            <body name="r_shoulder_1" pos="-0.0135187 -0.0670476 0.12352" quat="0.982708 -0.121688 -0.0429061 0.132799" gravcomp="0">
              <inertial pos="0.000172398 -0.0678405 0.000475572" quat="0.788783 0.116385 -0.055707 0.600977" mass="0.792282" diaginertia="0.00120905 0.00119544 0.000329558" />
              <joint name="r_shoulder_pitch" pos="0 0 0" axis="-3.35225e-07 1 -2.20686e-07" range="-2.96706 0.610865" damping="3" />
              <geom pos="0.0214149 0.106413 -0.168036" quat="0.788783 0.116385 -0.055707 0.600977" type="mesh" contype="0" conaffinity="0" rgba="0.7 0.7 0.7 1" mesh="sim_ecub_r_shoulder_1_prt" />
              <body name="r_shoulder_2" pos="0.00749996 -0.0933001 -6.00683e-07" gravcomp="0">
                <inertial pos="0.000512067 -0.000143644 -0.0364077" quat="0.99019 0.00208134 0.139708 -0.000293661" mass="0.710693" diaginertia="0.0203181 0.0203181 0.02" />
                <joint name="r_shoulder_roll" pos="0 0 0" axis="-1 1.71286e-07 2.92871e-07" range="-0.261799 2.61799" damping="2" />
                <geom pos="0.0139014 0.199666 -0.168047" quat="0.788783 0.116385 -0.055707 0.600977" type="mesh" contype="0" conaffinity="0"  rgba="0.7 0.7 0.7 1" mesh="sim_ecub_r_shoulder_2_prt" />
                <geom pos="0.0139014 0.199666 -0.168047" quat="0.788783 0.116385 -0.055707 0.600977" type="mesh" contype="0" conaffinity="0" rgba="0.7 0.7 0.7 1" mesh="sim_ecub_r_shoulder_3_prt" />
                <body name="r_upperarm" pos="-0.00684991 3.26793e-07 -0.0767999" gravcomp="0">
                  <inertial pos="0.000147064 -0.00233532 -0.0501167" quat="0.788783 0.116385 -0.055707 0.600977" mass="1.77224" diaginertia="0.00352386 0.00341014 0.00156558" />
                  <joint name="r_shoulder_yaw" pos="0 0 0" axis="1.71338e-07 -2.36593e-07 1" range="-0.872665 1.39626" damping="2" />
                  <geom pos="0.0207514 0.199666 -0.0912466" quat="0.788783 0.116385 -0.055707 0.600977" type="mesh" contype="0" conaffinity="0" rgba="0 0 0 1" mesh="sim_ecub_r_upperarm_prt" />
                  <body name="r_forearm" pos="0.01 0.00150007 -0.1237" gravcomp="0">
                    <inertial pos="0.00192384 0.00792081 -0.326384" quat="0.613625 0.238162 0.290072 0.694695" mass="1.47607" diaginertia="0.01 0.01 0.01" />
                    <joint name="r_elbow" pos="0 0 0" axis="3.35225e-07 -1 2.20686e-07" range="-0.0523599 1.309" damping="2" />
                    <geom pos="0.0107513 0.198166 0.032453" quat="0.788783 0.116385 -0.055707 0.600977" type="mesh" contype="0" conaffinity="0"  rgba="0.3 0.3 0.3 1" mesh="sim_ecub_r_forearm_prt" />
                    <geom pos="0.0107513 0.198166 0.032453" quat="0.788783 0.116385 -0.055707 0.600977" type="mesh"  contype="0" conaffinity="0" rgba="0.7 0.7 0.7 1" mesh="sim_ecub_r_wrist_1_prt" />
                    <geom pos="0.0107513 0.198166 0.032453" quat="0.788783 0.116385 -0.055707 0.600977" type="mesh" contype="0" conaffinity="0" rgba="1 0 0 1" mesh="sim_ecub_r_wrist_2_prt" />
                    <geom pos="0.0107513 0.198166 0.032453" quat="0.788783 0.116385 -0.055707 0.600977" type="mesh"  contype="0" conaffinity="0" rgba="0 0 1 1" mesh="sim_ecub_r_hand_palm_prt" />
                    <geom pos="0.0107513 0.198166 0.032453" quat="0.788783 0.116385 -0.055707 0.600977" type="mesh" contype="0" conaffinity="0" rgba="1 1 0 1" mesh="sim_ecub_r_hand_pinkie_1_prt" />
                    <geom pos="0.0107514 0.198166 0.032453" quat="0.788783 0.116385 -0.055707 0.600977" type="mesh" contype="0" conaffinity="0" rgba="1 0 1 1" mesh="sim_ecub_r_hand_pinkie_2_prt" />
                    <geom pos="0.0107513 0.198166 0.032453" quat="0.788783 0.116385 -0.055707 0.600977" type="mesh" contype="0" conaffinity="0" rgba="0 1 1 1" mesh="sim_ecub_r_hand_thumb_1_prt" />
                    <geom pos="0.0107513 0.198166 0.032453" quat="0.788783 0.116385 -0.055707 0.600977" type="mesh" contype="0" conaffinity="0" rgba="0 1 0 1" mesh="sim_ecub_r_hand_thumb_2_prt" />
                    <geom pos="0.0107513 0.198166 0.032453" quat="0.788783 0.116385 -0.055707 0.600977" type="mesh" contype="0" conaffinity="0" rgba="1 1 1 1" mesh="sim_ecub_r_hand_thumb_3_prt" />
                    <geom pos="0.0107513 0.198166 0.032453" quat="-0.788783 -0.116385 0.055707 -0.600977" type="mesh" contype="0" conaffinity="0" rgba="0 0 0.8 1" mesh="sim_ecub_r_hand_middle_1_prt" />
                    <geom pos="0.0107513 0.198166 0.032453" quat="-0.788783 -0.116385 0.055707 -0.600977" type="mesh" contype="0" conaffinity="0" rgba="0.1 0.8 0.1 1" mesh="sim_ecub_r_hand_middle_2_prt" />
                    <geom pos="0.0107513 0.198166 0.032453" quat="0.788783 0.116385 -0.055707 0.600977" type="mesh" mesh="sim_ecub_r_hand_ring_1_prt" />
                    <geom pos="0.0107513 0.198166 0.032453" quat="0.788783 0.116385 -0.055707 0.600977" type="mesh" contype="0" conaffinity="0" rgba="0 1 0 1" mesh="sim_ecub_r_hand_ring_2_prt" />
                    <geom pos="0.0107513 0.198166 0.032453" quat="0.788783 0.116385 -0.055707 0.600977" type="mesh" contype="0" conaffinity="0" rgba="0 0 0 1" mesh="sim_ecub_r_hand_index_1_prt" />
                    <geom pos="0.0107513 0.198166 0.032453" quat="0.788783 0.116385 -0.055707 0.600977" type="mesh" contype="0" conaffinity="0" rgba="1 0 0 1" mesh="sim_ecub_r_hand_index_2_prt" />
                    <geom pos="0.0107514 0.198166 0.032453" quat="0.788783 0.116385 -0.055707 0.600977" type="mesh" contype="0" conaffinity="0" rgba="0 0 1 1" mesh="sim_ecub_r_hand_index_3_prt" />
                  </body>
                </body>
              </body>
            </body>
            <body name="l_shoulder_1" pos="-0.0135187 0.0670476 0.12352" quat="0.982708 0.121688 -0.0429058 -0.132799" gravcomp="0">
              <inertial pos="0.000148281 0.0678296 0.000503488" quat="0.0086468 -0.011851 0.711187 0.70285" mass="0.791376" diaginertia="0.00120905 0.00119544 0.000329558" />
              <joint name="l_shoulder_pitch" pos="0 0 0" axis="1.4959e-07 1 2.72203e-07" range="-2.96706 0.610865" damping="2" />
              <geom pos="0.0214151 -0.106413 -0.168036" quat="0.600977 -0.0557072 0.116385 0.788783" type="mesh" contype="0" conaffinity="0" rgba="0.7 0.7 0.7 1" mesh="sim_ecub_l_shoulder_1_prt" />
              <body name="l_shoulder_2" pos="0.00500013 0.0932995 -4.34136e-07" gravcomp="0">
                <inertial pos="0.00302787 0.000128307 -0.0364069" quat="0.68686 0.173186 0.172996 0.684326" mass="0.712399" diaginertia="0.000824775 0.000759006 0.000323849" />
                <joint name="l_shoulder_roll" pos="0 0 0" axis="1 3.5692e-07 2.72158e-07" range="-0.261799 2.61799" damping="2" />
                <geom pos="0.0164285 -0.199759 -0.168024" quat="0.600977 -0.0557072 0.116385 0.788783" type="mesh" contype="0" conaffinity="0" rgba="0.7 0.7 0.7 1" mesh="sim_ecub_l_shoulder_2_prt" />
                <geom pos="0.0164285 -0.199759 -0.168024" quat="0.600977 -0.0557072 0.116385 0.788783" type="mesh" contype="0" conaffinity="0" rgba="0.7 0.7 0.7 1" mesh="sim_ecub_l_shoulder_3_prt" />
                <body name="l_upperarm" pos="-0.00435007 2.43599e-07 -0.0768001" gravcomp="0">
                  <inertial pos="0.00013045 0.00225331 -0.0500647" quat="0.610168 0.0102954 -0.0258805 0.791783" mass="1.77085" diaginertia="0.00352386 0.00341014 0.00156558" />
                  <joint name="l_shoulder_yaw" pos="0 0 0" axis="3.93691e-07 -1.85076e-07 -1" range="-0.872665 1.39626" damping="2" />
                  <geom pos="0.0207786 -0.19976 -0.0912239" quat="0.600977 -0.0557072 0.116385 0.788783" type="mesh" contype="0" conaffinity="0" rgba="1 1 0 1" mesh="sim_ecub_l_upperarm_prt" />
                  <body name="l_forearm" pos="0.0100001 -0.00150006 -0.1237" gravcomp="0">
                    <inertial pos="0.00192604 -0.00793183 -0.326506" quat="0.693294 0.293184 0.24049 0.612822" mass="1.47607" diaginertia="0.01 0.01 0.01"/>
                    <joint name="l_elbow" pos="0 0 0" axis="-1.4959e-07 -1 -2.72203e-07" range="-0.0523599 1.309" damping="2" />
                    <geom pos="0.0107785 -0.19826 0.0324758" quat="0.600977 -0.0557072 0.116385 0.788783" type="mesh" contype="0" conaffinity="0" rgba="0.3 0.3 0.3 1" mesh="sim_ecub_l_forearm_prt" />
                    <geom pos="0.0107785 -0.19826 0.0324758" quat="0.600977 -0.0557072 0.116385 0.788783" type="mesh" contype="0" conaffinity="0" rgba="0.7 0.7 0.7 1" mesh="sim_ecub_l_wrist_1_prt" />
                    <geom pos="0.0107785 -0.19826 0.0324758" quat="0.600977 -0.0557072 0.116385 0.788783" type="mesh" contype="0" conaffinity="0" rgba="1 0 1 1" mesh="sim_ecub_l_wrist_2_prt" />
                    <geom pos="0.0107785 -0.19826 0.0324758" quat="0.600977 -0.0557072 0.116385 0.788783" type="mesh" contype="0" conaffinity="0" rgba="0 1 1 1" mesh="sim_ecub_l_hand_palm_prt" />
                    <geom pos="0.0107785 -0.19826 0.0324758" quat="0.600977 -0.0557073 0.116385 0.788783" type="mesh" contype="0" conaffinity="0" rgba="0 1 0 1" mesh="sim_ecub_l_hand_ring_1_prt" />
                    <geom pos="0.0107784 -0.19826 0.0324758" quat="0.600977 -0.0557073 0.116385 0.788783" type="mesh" contype="0" conaffinity="0"  rgba="1 1 1 1" mesh="sim_ecub_l_hand_ring_2_prt" />
                    <geom pos="0.0107785 -0.19826 0.0324758" quat="0.600977 -0.0557072 0.116385 0.788783" type="mesh" contype="0" conaffinity="0" rgba="0 0 0.8 1" mesh="sim_ecub_l_hand_index_1_prt" />
                    <geom pos="0.0107785 -0.19826 0.0324758" quat="0.600977 -0.0557072 0.116385 0.788783" type="mesh" contype="0" conaffinity="0" rgba="0.1 0.8 0.1 1" mesh="sim_ecub_l_hand_index_2_prt" />
                    <geom pos="0.0107786 -0.19826 0.0324758" quat="0.600977 -0.0557072 0.116385 0.788783" type="mesh" mesh="sim_ecub_l_hand_index_3_prt" />
                    <geom pos="0.0107785 -0.19826 0.0324758" quat="0.600977 -0.0557072 0.116385 0.788783" type="mesh" contype="0" conaffinity="0" rgba="0 1 0 1" mesh="sim_ecub_l_hand_middle_1_prt" />
                    <geom pos="0.0107785 -0.19826 0.0324758" quat="0.600977 -0.0557072 0.116385 0.788783" type="mesh" contype="0" conaffinity="0" rgba="0 0 0 1" mesh="sim_ecub_l_hand_middle_2_prt" />
                    <geom pos="0.0107785 -0.19826 0.0324758" quat="0.600977 -0.0557072 0.116385 0.788783" type="mesh" contype="0" conaffinity="0"  rgba="1 0 0 1" mesh="sim_ecub_l_hand_thumb_1_prt" />
                    <geom pos="0.0107785 -0.19826 0.0324758" quat="-0.600977 0.0557072 -0.116385 -0.788783" type="mesh" contype="0" conaffinity="0" rgba="0 0 1 1" mesh="sim_ecub_l_hand_thumb_2_prt" />
                    <geom pos="0.0107785 -0.19826 0.0324758" quat="-0.600977 0.0557072 -0.116385 -0.788783" type="mesh" contype="0" conaffinity="0"  rgba="1 1 0 1" mesh="sim_ecub_l_hand_thumb_3_prt" />
                    <geom pos="0.0107785 -0.19826 0.0324758" quat="0.600977 -0.0557073 0.116385 0.788783" type="mesh" contype="0" conaffinity="0" rgba="1 0 1 1" mesh="sim_ecub_l_hand_pinkie_1_prt" />
                    <geom pos="0.0107786 -0.19826 0.0324758" quat="0.600977 -0.0557073 0.116385 0.788783" type="mesh" contype="0" conaffinity="0" rgba="0 1 1 1" mesh="sim_ecub_l_hand_pinkie_2_prt" />
                  </body>
                </body>
              </body>
            </body>
          </body>
        </body>
      </body>
    </body>
  <geom name="floor" size="0 0 .05" type="plane" material="grid" condim="3" /></worldbody>
<actuator>
 <general class = "pos_control" name="r_hip_pitch" joint="r_hip_pitch"  ctrlrange="-0.785398 2.00713" />
 <general class = "pos_control" name="r_hip_roll" joint="r_hip_roll"  ctrlrange="-100 100" />
 <general class = "pos_control" name="r_hip_yaw" joint="r_hip_yaw"  ctrlrange="-100 100" />
 <general class = "pos_control" name="r_knee" joint="r_knee"  ctrlrange="-100 100" />
 <general class = "pos_control" name="r_ankle_pitch" joint="r_ankle_pitch"  ctrlrange="-100 100" />
 <general class = "pos_control" name="r_ankle_roll" joint="r_ankle_roll"  ctrlrange="-100 100" />
 <general class = "pos_control" name="l_hip_pitch" joint="l_hip_pitch"  ctrlrange="-100 100" />
 <general class = "pos_control" name="l_hip_roll" joint="l_hip_roll"  ctrlrange="-100 100" />
 <general class = "pos_control" name="l_hip_yaw" joint="l_hip_yaw"  ctrlrange="-100 100" />
 <general class = "pos_control" name="l_knee" joint="l_knee"  ctrlrange="-100 100" />
 <general class = "pos_control" name="l_ankle_pitch" joint="l_ankle_pitch"  ctrlrange="-100 100" />
 <general class = "pos_control" name="l_ankle_roll" joint="l_ankle_roll"  ctrlrange="-100 100" />
 <general class = "pos_control" name="torso_pitch" joint="torso_pitch"  ctrlrange="-100 100" />
 <general class = "pos_control" name="torso_roll" joint="torso_roll"  ctrlrange="-100 100" />
 <general class = "pos_control" name="torso_yaw" joint="torso_yaw"  ctrlrange="-100 100" />
 <general class = "pos_control" name="r_shoulder_pitch" joint="r_shoulder_pitch"  ctrlrange="-100 100" />
 <general class = "pos_control" name="r_shoulder_roll" joint="r_shoulder_roll"  ctrlrange="-100 100" />
 <general class = "pos_control" name="r_shoulder_yaw" joint="r_shoulder_yaw"  ctrlrange="-100 100" />
 <general class = "pos_control" name="r_elbow" joint="r_elbow"  ctrlrange="-100 100" />
 <general class = "pos_control" name="l_shoulder_pitch" joint="l_shoulder_pitch"  ctrlrange="-100 100" />
 <general class = "pos_control" name="l_shoulder_roll" joint="l_shoulder_roll"  ctrlrange="-100 100" />
 <general class = "pos_control" name="l_shoulder_yaw" joint="l_shoulder_yaw"  ctrlrange="-100 100" />
 <general class = "pos_control" name="l_elbow" joint="l_elbow" ctrlrange="-100 100" />
 <!-- <motor name="r_hip_pitch" joint="r_hip_pitch" gear="1" ctrlrange="-100 100" />
 <motor name="r_hip_roll" joint="r_hip_roll" gear="1" ctrlrange="-100 100" />
 <motor name="r_hip_yaw" joint="r_hip_yaw" gear="1" ctrlrange="-100 100" />
 <motor name="r_knee" joint="r_knee" gear="1" ctrlrange="-100 100" />
 <motor name="r_ankle_pitch" joint="r_ankle_pitch" gear="1" ctrlrange="-100 100" />
 <motor name="r_ankle_roll" joint="r_ankle_roll" gear="1" ctrlrange="-100 100" />
 <motor name="l_hip_pitch" joint="l_hip_pitch" gear="1" ctrlrange="-100 100" />
 <motor name="l_hip_roll" joint="l_hip_roll" gear="1" ctrlrange="-100 100" />
 <motor name="l_hip_yaw" joint="l_hip_yaw" gear="1" ctrlrange="-100 100" />
 <motor name="l_knee" joint="l_knee" gear="1" ctrlrange="-100 100" />
 <motor name="l_ankle_pitch" joint="l_ankle_pitch" gear="1" ctrlrange="-100 100" />
 <motor name="l_ankle_roll" joint="l_ankle_roll" gear="1" ctrlrange="-100 100" />
 <motor name="torso_pitch" joint="torso_pitch" gear="1" ctrlrange="-100 100" />
 <motor name="torso_roll" joint="torso_roll" gear="1" ctrlrange="-100 100" />
 <motor name="torso_yaw" joint="torso_yaw" gear="1" ctrlrange="-100 100" />
 <motor name="r_shoulder_pitch" joint="r_shoulder_pitch" gear="1" ctrlrange="-100 100" />
 <motor name="r_shoulder_roll" joint="r_shoulder_roll" gear="1" ctrlrange="-100 100" />
 <motor name="r_shoulder_yaw" joint="r_shoulder_yaw" gear="1" ctrlrange="-100 100" />
 <motor name="r_elbow" joint="r_elbow" gear="1" ctrlrange="-100 100" />
 <motor name="l_shoulder_pitch" joint="l_shoulder_pitch" gear="1" ctrlrange="-100 100" />
 <motor name="l_shoulder_roll" joint="l_shoulder_roll" gear="1" ctrlrange="-100 100" />
 <motor name="l_shoulder_yaw" joint="l_shoulder_yaw" gear="1" ctrlrange="-100 100" />
 <motor name="l_elbow" joint="l_elbow" gear="1" ctrlrange="-100 100" />
 -->
 </actuator> 
 
 <asset><texture type="skybox" builtin="gradient" rgb1=".3 .5 .7" rgb2="0 0 0" width="32" height="512" /><texture name="body" type="cube" builtin="flat" mark="cross" rgb1="0.8 0.6 0.4" rgb2="0.8 0.6 0.4" width="127" height="1278" markrgb="1 1 1" random="0.01" /><texture name="grid" type="2d" builtin="checker" rgb1=".1 .2 .3" rgb2=".2 .3 .4" width="512" height="512" /><material name="body" texture="body" texuniform="true" rgba="0.8 0.6 .4 1" /><material name="grid" texture="grid" texrepeat="1 1" texuniform="true" reflectance=".2" /></asset></mujoco>